Workbook

Sheet Suivi
B1: Suivi de la prospection
B3: Statut | C3: Total | D3: Vague 1 | E3: Vague 2 | F3: Vague 3
B4: À contacter | C4: =COUNTIF(Prospects!$K$5:$K$51,B4) -> 47 | D4: =COUNTIFS(Prospects!$K$5:$K$51,$B4,Prospects!$B$5:$B$51,1) -> 20 | E4: =COUNTIFS(Prospects!$K$5:$K$51,$B4,Prospects!$B$5:$B$51,2) -> 16 | F4: =COUNTIFS(Prospects!$K$5:$K$51,$B4,Prospects!$B$5:$B$51,3) -> 11
B5: Message envoyé | C5: =COUNTIF(Prospects!$K$5:$K$51,B5) -> 0 | D5: =COUNTIFS(Prospects!$K$5:$K$51,$B5,Prospects!$B$5:$B$51,1) -> 0 | E5: =COUNTIFS(Prospects!$K$5:$K$51,$B5,Prospects!$B$5:$B$51,2) -> 0 | F5: =COUNTIFS(Prospects!$K$5:$K$51,$B5,Prospects!$B$5:$B$51,3) -> 0
B6: Relance 1 faite | C6: =COUNTIF(Prospects!$K$5:$K$51,B6) -> 0 | D6: =COUNTIFS(Prospects!$K$5:$K$51,$B6,Prospects!$B$5:$B$51,1) -> 0 | E6: =COUNTIFS(Prospects!$K$5:$K$51,$B6,Prospects!$B$5:$B$51,2) -> 0 | F6: =COUNTIFS(Prospects!$K$5:$K$51,$B6,Prospects!$B$5:$B$51,3) -> 0
B7: Relance 2 faite | C7: =COUNTIF(Prospects!$K$5:$K$51,B7) -> 0 | D7: =COUNTIFS(Prospects!$K$5:$K$51,$B7,Prospects!$B$5:$B$51,1) -> 0 | E7: =COUNTIFS(Prospects!$K$5:$K$51,$B7,Prospects!$B$5:$B$51,2) -> 0 | F7: =COUNTIFS(Prospects!$K$5:$K$51,$B7,Prospects!$B$5:$B$51,3) -> 0
B8: A répondu | C8: =COUNTIF(Prospects!$K$5:$K$51,B8) -> 0 | D8: =COUNTIFS(Prospects!$K$5:$K$51,$B8,Prospects!$B$5:$B$51,1) -> 0 | E8: =COUNTIFS(Prospects!$K$5:$K$51,$B8,Prospects!$B$5:$B$51,2) -> 0 | F8: =COUNTIFS(Prospects!$K$5:$K$51,$B8,Prospects!$B$5:$B$51,3) -> 0
B9: Démo prévue | C9: =COUNTIF(Prospects!$K$5:$K$51,B9) -> 0 | D9: =COUNTIFS(Prospects!$K$5:$K$51,$B9,Prospects!$B$5:$B$51,1) -> 0 | E9: =COUNTIFS(Prospects!$K$5:$K$51,$B9,Prospects!$B$5:$B$51,2) -> 0 | F9: =COUNTIFS(Prospects!$K$5:$K$51,$B9,Prospects!$B$5:$B$51,3) -> 0
B10: Démo faite | C10: =COUNTIF(Prospects!$K$5:$K$51,B10) -> 0 | D10: =COUNTIFS(Prospects!$K$5:$K$51,$B10,Prospects!$B$5:$B$51,1) -> 0 | E10: =COUNTIFS(Prospects!$K$5:$K$51,$B10,Prospects!$B$5:$B$51,2) -> 0 | F10: =COUNTIFS(Prospects!$K$5:$K$51,$B10,Prospects!$B$5:$B$51,3) -> 0
B11: Client | C11: =COUNTIF(Prospects!$K$5:$K$51,B11) -> 0 | D11: =COUNTIFS(Prospects!$K$5:$K$51,$B11,Prospects!$B$5:$B$51,1) -> 0 | E11: =COUNTIFS(Prospects!$K$5:$K$51,$B11,Prospects!$B$5:$B$51,2) -> 0 | F11: =COUNTIFS(Prospects!$K$5:$K$51,$B11,Prospects!$B$5:$B$51,3) -> 0
B12: Pas intéressé | C12: =COUNTIF(Prospects!$K$5:$K$51,B12) -> 0 | D12: =COUNTIFS(Prospects!$K$5:$K$51,$B12,Prospects!$B$5:$B$51,1) -> 0 | E12: =COUNTIFS(Prospects!$K$5:$K$51,$B12,Prospects!$B$5:$B$51,2) -> 0 | F12: =COUNTIFS(Prospects!$K$5:$K$51,$B12,Prospects!$B$5:$B$51,3) -> 0
B13: Sans réponse | C13: =COUNTIF(Prospects!$K$5:$K$51,B13) -> 0 | D13: =COUNTIFS(Prospects!$K$5:$K$51,$B13,Prospects!$B$5:$B$51,1) -> 0 | E13: =COUNTIFS(Prospects!$K$5:$K$51,$B13,Prospects!$B$5:$B$51,2) -> 0 | F13: =COUNTIFS(Prospects!$K$5:$K$51,$B13,Prospects!$B$5:$B$51,3) -> 0
B14: Total | C14: =SUM(C4:C13) -> 47
B16: Indicateurs
B17: Entreprises contactées | C17: =C14-C4 -> 0
B18: Ont répondu (ou plus loin) | C18: =C8+C9+C10+C11 -> 0
B19: Taux de réponse | C19: =IF(C17=0,"-",C18/C17) -> -
B20: Démos faites | C20: =C10+C11 -> 0
B21: Clients | C21: =C11 -> 0
B23: Le taux de réponse compte « A répondu », « Démo prévue », « Démo faite » et « Client ».

Sheet Prospects
A1: Prospection : template « Gestion de stock » et système automatisé
A2: Jaune = à remplir · Gris = automatique · Cliquez sur « Ouvrir WhatsApp » : le message 1 est déjà écrit, ajoutez la vidéo puis envoyez.
A4: N° | B4: Vague | C4: Priorité | D4: Entreprise | E4: Ville | F4: Téléphone | G4: WhatsApp | H4: Type (fichier) | I4: Segment | J4: Date du 1er message | K4: Statut | L4: Relance 1 le | M4: Relance 2 le | N4: Prochaine action | O4: Réponse / notes | P4: À vérifier
A5: 5 | B5: 1 | C5: A | D5: LOSAKO SHAP | E5: Kinshasa | F5: +243 821 006 430 | G5: Ouvrir WhatsApp | H5: Magasin de telephone | I5: Téléphones, électronique, informatique | K5: À contacter | L5: =IF(J5="","",J5+3) | M5: =IF(J5="","",J5+7) | N5: =IF(K5="À contacter","Envoyer message 1 + vidéo présentation",IF(K5="Message envoyé",IF(J5="","Indiquer la date d'envoi",IF(TODAY()>=J5+3,"Envoyer la relance 1","Attendre la réponse")),IF(K5="Relance 1 faite",IF(TODAY()>=J5+7,"Envoyer la relance 2","Attendre la réponse"),IF(K5="Relance 2 faite","Si rien sous 3 jours : Sans réponse",IF(K5="A répondu","Envoyer message 2 + vidéo workflow",IF(K5="Démo prévue","Préparer la démo avec ses produits",IF(K5="Démo faite","Envoyer l'offre et le prix",IF(K5="Client","Installer et demander un avis","Fini")))))))) -> Envoyer message 1 + vidéo présentation
A6: 37 | B6: 1 | C6: A | D6: ELECTRONIC STORE | E6: Kinshasa | F6: +243 999 912 239 | G6: Ouvrir WhatsApp | H6: Electronique | I6: Téléphones, électronique, informatique | K6: À contacter | L6: =IF(J6="","",J6+3) | M6: =IF(J6="","",J6+7) | N6: =IF(K6="À contacter","Envoyer message 1 + vidéo présentation",IF(K6="Message envoyé",IF(J6="","Indiquer la date d'envoi",IF(TODAY()>=J6+3,"Envoyer la relance 1","Attendre la réponse")),IF(K6="Relance 1 faite",IF(TODAY()>=J6+7,"Envoyer la relance 2","Attendre la réponse"),IF(K6="Relance 2 faite","Si rien sous 3 jours : Sans réponse",IF(K6="A répondu","Envoyer message 2 + vidéo workflow",IF(K6="Démo prévue","Préparer la démo avec ses produits",IF(K6="Démo faite","Envoyer l'offre et le prix",IF(K6="Client","Installer et demander un avis","Fini")))))))) -> Envoyer message 1 + vidéo présentation | P6: Nom corrigé (fichier : ELETRONIC STORE)
A7: 38 | B7: 1 | C7: A | D7: MI KINSHASA | E7: Kinshasa | F7: +243 816 812 630 | G7: Ouvrir WhatsApp | H7: Magasin de telephone | I7: Téléphones, électronique, informatique | K7: À contacter | L7: =IF(J7="","",J7+3) | M7: =IF(J7="","",J7+7) | N7: =IF(K7="À contacter","Envoyer message 1 + vidéo présentation",IF(K7="Message envoyé",IF(J7="","Indiquer la date d'envoi",IF(TODAY()>=J7+3,"Envoyer la relance 1","Attendre la réponse")),IF(K7="Relance 1 faite",IF(TODAY()>=J7+7,"Envoyer la relance 2","Attendre la réponse"),IF(K7="Relance 2 faite","Si rien sous 3 jours : Sans réponse",IF(K7="A répondu","Envoyer message 2 + vidéo workflow",IF(K7="Démo prévue","Préparer la démo avec ses produits",IF(K7="Démo faite","Envoyer l'offre et le prix",IF(K7="Client","Installer et demander un avis","Fini")))))))) -> Envoyer message 1 + vidéo présentation
A8: 39 | B8: 1 | C8: A | D8: XIAOMI STORE KINSHASA | E8: Kinshasa | F8: +243 902 301 721 | G8: Ouvrir WhatsApp | H8: Magasin de telephone | I8: Téléphones, électronique, informatique | K8: À contacter | L8: =IF(J8="","",J8+3) | M8: =IF(J8="","",J8+7) | N8: =IF(K8="À contacter","Envoyer message 1 + vidéo présentation",IF(K8="Message envoyé",IF(J8="","Indiquer la date d'envoi",IF(TODAY()>=J8+3,"Envoyer la relance 1","Attendre la réponse")),IF(K8="Relance 1 faite",IF(TODAY()>=J8+7,"Envoyer la relance 2","Attendre la réponse"),IF(K8="Relance 2 faite","Si rien sous 3 jours : Sans réponse",IF(K8="A répondu","Envoyer message 2 + vidéo workflow",IF(K8="Démo prévue","Préparer la démo avec ses produits",IF(K8="Démo faite","Envoyer l'offre et le prix",IF(K8="Client","Installer et demander un avis","Fini")))))))) -> Envoyer message 1 + vidéo présentation | P8: Nom corrigé (fichier : XIAIMI STORE KINSHASA)
A9: 40 | B9: 1 | C9: A | D9: MICROCONCEPT | E9: Kinshasa | F9: +243 812 662 378 | G9: Ouvrir WhatsApp | H9: Electronique | I9: Téléphones, électronique, informatique | K9: À contacter | L9: =IF(J9="","",J9+3) | M9: =IF(J9="","",J9+7) | N9: =IF(K9="À contacter","Envoyer message 1 + vidéo présentation",IF(K9="Message envoyé",IF(J9="","Indiquer la date d'envoi",IF(TODAY()>=J9+3,"Envoyer la relance 1","Attendre la réponse")),IF(K9="Relance 1 faite",IF(TODAY()>=J9+7,"Envoyer la relance 2","Attendre la réponse"),IF(K9="Relance 2 faite","Si rien sous 3 jours : Sans réponse",IF(K9="A répondu","Envoyer message 2 + vidéo workflow",IF(K9="Démo prévue","Préparer la démo avec ses produits",IF(K9="Démo faite","Envoyer l'offre et le prix",IF(K9="Client","Installer et demander un avis","Fini")))))))) -> Envoyer message 1 + vidéo présentation
A10: 41 | B10: 1 | C10: A | D10: LNK AFRICA 2 | E10: Kinshasa | F10: +243 811 558 008 | G10: Ouvrir WhatsApp | H10: Electronique | I10: Téléphones, électronique, informatique | K10: À contacter | L10: =IF(J10="","",J10+3) | M10: =IF(J10="","",J10+7) | N10: =IF(K10="À contacter","Envoyer message 1 + vidéo présentation",IF(K10="Message envoyé",IF(J10="","Indiquer la date d'envoi",IF(TODAY()>=J10+3,"Envoyer la relance 1","Attendre la réponse")),IF(K10="Relance 1 faite",IF(TODAY()>=J10+7,"Envoyer la relance 2","Attendre la réponse"),IF(K10="Relance 2 faite","Si rien sous 3 jours : Sans réponse",IF(K10="A répondu","Envoyer message 2 + vidéo workflow",IF(K10="Démo prévue","Préparer la démo avec ses produits",IF(K10="Démo faite","Envoyer l'offre et le prix",IF(K10="Client","Installer et demander un avis","Fini")))))))) -> Envoyer message 1 + vidéo présentation
A11: 10 | B11: 1 | C11: A | D11: 5G STORE | E11: Lubumbashi | F11: +243 815 682 171 | G11: Ouvrir WhatsApp | H11: Magasin de telephone | I11: Téléphones, électronique, informatique | K11: À contacter | L11: =IF(J11="","",J11+3) | M11: =IF(J11="","",J11+7) | N11: =IF(K11="À contacter","Envoyer message 1 + vidéo présentation",IF(K11="Message envoyé",IF(J11="","Indiquer la date d'envoi",IF(TODAY()>=J11+3,"Envoyer la relance 1","Attendre la réponse")),IF(K11="Relance 1 faite",IF(TODAY()>=J11+7,"Envoyer la relance 2","Attendre la réponse"),IF(K11="Relance 2 faite","Si rien sous 3 jours : Sans réponse",IF(K11="A répondu","Envoyer message 2 + vidéo workflow",IF(K11="Démo prévue","Préparer la démo avec ses produits",IF(K11="Démo faite","Envoyer l'offre et le prix",IF(K11="Client","Installer et demander un avis","Fini")))))))) -> Envoyer message 1 + vidéo présentation
A12: 11 | B12: 1 | C12: A | D12: CLASS MOBILE | E12: Lubumbashi | F12: +243 906 900 600 | G12: Ouvrir WhatsApp | H12: Electronique | I12: Téléphones, électronique, informatique | K12: À contacter | L12: =IF(J12="","",J12+3) | M12: =IF(J12="","",J12+7) | N12: =IF(K12="À contacter","Envoyer message 1 + vidéo présentation",IF(K12="Message envoyé",IF(J12="","Indiquer la date d'envoi",IF(TODAY()>=J12+3,"Envoyer la relance 1","Attendre la réponse")),IF(K12="Relance 1 faite",IF(TODAY()>=J12+7,"Envoyer la relance 2","Attendre la réponse"),IF(K12="Relance 2 faite","Si rien sous 3 jours : Sans réponse",IF(K12="A répondu","Envoyer message 2 + vidéo workflow",IF(K12="Démo prévue","Préparer la démo avec ses produits",IF(K12="Démo faite","Envoyer l'offre et le prix",IF(K12="Client","Installer et demander un avis","Fini")))))))) -> Envoyer message 1 + vidéo présentation
A13: 20 | B13: 1 | C13: A | D13: VIP INFORMATIQUE | E13: Lubumbashi | F13: +243 854 700 000 | G13: Ouvrir WhatsApp | H13: Electronique | I13: Téléphones, électronique, informatique | K13: À contacter | L13: =IF(J13="","",J13+3) | M13: =IF(J13="","",J13+7) | N13: =IF(K13="À contacter","Envoyer message 1 + vidéo présentation",IF(K13="Message envoyé",IF(J13="","Indiquer la date d'envoi",IF(TODAY()>=J13+3,"Envoyer la relance 1","Attendre la réponse")),IF(K13="Relance 1 faite",IF(TODAY()>=J13+7,"Envoyer la relance 2","Attendre la réponse"),IF(K13="Relance 2 faite","Si rien sous 3 jours : Sans réponse",IF(K13="A répondu","Envoyer message 2 + vidéo workflow",IF(K13="Démo prévue","Préparer la démo avec ses produits",IF(K13="Démo faite","Envoyer l'offre et le prix",IF(K13="Client","Installer et demander un avis","Fini")))))))) -> Envoyer message 1 + vidéo présentation
A14: 21 | B14: 1 | C14: A | D14: SPACE-X COMPUTERS | E14: Lubumbashi | F14: +243 970 278 527 | G14: Ouvrir WhatsApp | H14: Informatique | I14: Téléphones, électronique, informatique | K14: À contacter | L14: =IF(J14="","",J14+3) | M14: =IF(J14="","",J14+7) | N14: =IF(K14="À contacter","Envoyer message 1 + vidéo présentation",IF(K14="Message envoyé",IF(J14="","Indiquer la date d'envoi",IF(TODAY()>=J14+3,"Envoyer la relance 1","Attendre la réponse")),IF(K14="Relance 1 faite",IF(TODAY()>=J14+7,"Envoyer la relance 2","Attendre la réponse"),IF(K14="Relance 2 faite","Si rien sous 3 jours : Sans réponse",IF(K14="A répondu","Envoyer message 2 + vidéo workflow",IF(K14="Démo prévue","Préparer la démo avec ses produits",IF(K14="Démo faite","Envoyer l'offre et le prix",IF(K14="Client","Installer et demander un avis","Fini")))))))) -> Envoyer message 1 + vidéo présentation
A15: 22 | B15: 1 | C15: A | D15: BIBIN BUSINESS | E15: Lubumbashi | F15: +243 843 295 999 | G15: Ouvrir WhatsApp | H15: Electronique | I15: Téléphones, électronique, informatique | K15: À contacter | L15: =IF(J15="","",J15+3) | M15: =IF(J15="","",J15+7) | N15: =IF(K15="À contacter","Envoyer message 1 + vidéo présentation",IF(K15="Message envoyé",IF(J15="","Indiquer la date d'envoi",IF(TODAY()>=J15+3,"Envoyer la relance 1","Attendre la réponse")),IF(K15="Relance 1 faite",IF(TODAY()>=J15+7,"Envoyer la relance 2","Attendre la réponse"),IF(K15="Relance 2 faite","Si rien sous 3 jours : Sans réponse",IF(K15="A répondu","Envoyer message 2 + vidéo workflow",IF(K15="Démo prévue","Préparer la démo avec ses produits",IF(K15="Démo faite","Envoyer l'offre et le prix",IF(K15="Client","Installer et demander un avis","Fini")))))))) -> Envoyer message 1 + vidéo présentation
A16: 26 | B16: 1 | C16: A | D16: BEST BUY CONGO SARL | E16: Lubumbashi | F16: +243 812 626 000 | G16: Ouvrir WhatsApp | H16: Electronique | I16: Téléphones, électronique, informatique | K16: À contacter | L16: =IF(J16="","",J16+3) | M16: =IF(J16="","",J16+7) | N16: =IF(K16="À contacter","Envoyer message 1 + vidéo présentation",IF(K16="Message envoyé",IF(J16="","Indiquer la date d'envoi",IF(TODAY()>=J16+3,"Envoyer la relance 1","Attendre la réponse")),IF(K16="Relance 1 faite",IF(TODAY()>=J16+7,"Envoyer la relance 2","Attendre la réponse"),IF(K16="Relance 2 faite","Si rien sous 3 jours : Sans réponse",IF(K16="A répondu","Envoyer message 2 + vidéo workflow",IF(K16="Démo prévue","Préparer la démo avec ses produits",IF(K16="Démo faite","Envoyer l'offre et le prix",IF(K16="Client","Installer et demander un avis","Fini")))))))) -> Envoyer message 1 + vidéo présentation
A17: 27 | B17: 1 | C17: A | D17: NOBLE ELECTRONIQUE | E17: Lubumbashi | F17: +243 975 222 660 | G17: Ouvrir WhatsApp | H17: Electronique | I17: Téléphones, électronique, informatique | K17: À contacter | L17: =IF(J17="","",J17+3) | M17: =IF(J17="","",J17+7) | N17: =IF(K17="À contacter","Envoyer message 1 + vidéo présentation",IF(K17="Message envoyé",IF(J17="","Indiquer la date d'envoi",IF(TODAY()>=J17+3,"Envoyer la relance 1","Attendre la réponse")),IF(K17="Relance 1 faite",IF(TODAY()>=J17+7,"Envoyer la relance 2","Attendre la réponse"),IF(K17="Relance 2 faite","Si rien sous 3 jours : Sans réponse",IF(K17="A répondu","Envoyer message 2 + vidéo workflow",IF(K17="Démo prévue","Préparer la démo avec ses produits",IF(K17="Démo faite","Envoyer l'offre et le prix",IF(K17="Client","Installer et demander un avis","Fini")))))))) -> Envoyer message 1 + vidéo présentation
A18: 29 | B18: 1 | C18: A | D18: DEALST | E18: Lubumbashi | F18: +243 994 797 830 | G18: Ouvrir WhatsApp | H18: Jeux et informatique | I18: Téléphones, électronique, informatique | K18: À contacter | L18: =IF(J18="","",J18+3) | M18: =IF(J18="","",J18+7) | N18: =IF(K18="À contacter","Envoyer message 1 + vidéo présentation",IF(K18="Message envoyé",IF(J18="","Indiquer la date d'envoi",IF(TODAY()>=J18+3,"Envoyer la relance 1","Attendre la réponse")),IF(K18="Relance 1 faite",IF(TODAY()>=J18+7,"Envoyer la relance 2","Attendre la réponse"),IF(K18="Relance 2 faite","Si rien sous 3 jours : Sans réponse",IF(K18="A répondu","Envoyer message 2 + vidéo workflow",IF(K18="Démo prévue","Préparer la démo avec ses produits",IF(K18="Démo faite","Envoyer l'offre et le prix",IF(K18="Client","Installer et demander un avis","Fini")))))))) -> Envoyer message 1 + vidéo présentation
A19: 30 | B19: 1 | C19: A | D19: TIM SHOP | E19: Lubumbashi | F19: +243 832 592 599 | G19: Ouvrir WhatsApp | H19: Magasin de telephone | I19: Téléphones, électronique, informatique | K19: À contacter | L19: =IF(J19="","",J19+3) | M19: =IF(J19="","",J19+7) | N19: =IF(K19="À contacter","Envoyer message 1 + vidéo présentation",IF(K19="Message envoyé",IF(J19="","Indiquer la date d'envoi",IF(TODAY()>=J19+3,"Envoyer la relance 1","Attendre la réponse")),IF(K19="Relance 1 faite",IF(TODAY()>=J19+7,"Envoyer la relance 2","Attendre la réponse"),IF(K19="Relance 2 faite","Si rien sous 3 jours : Sans réponse",IF(K19="A répondu","Envoyer message 2 + vidéo workflow",IF(K19="Démo prévue","Préparer la démo avec ses produits",IF(K19="Démo faite","Envoyer l'offre et le prix",IF(K19="Client","Installer et demander un avis","Fini")))))))) -> Envoyer message 1 + vidéo présentation
A20: 32 | B20: 1 | C20: A | D20: QUIN ELECTRO | E20: Lubumbashi | F20: +243 850 784 589 | G20: Ouvrir WhatsApp | H20: Electronique | I20: Téléphones, électronique, informatique | K20: À contacter | L20: =IF(J20="","",J20+3) | M20: =IF(J20="","",J20+7) | N20: =IF(K20="À contacter","Envoyer message 1 + vidéo présentation",IF(K20="Message envoyé",IF(J20="","Indiquer la date d'envoi",IF(TODAY()>=J20+3,"Envoyer la relance 1","Attendre la réponse")),IF(K20="Relance 1 faite",IF(TODAY()>=J20+7,"Envoyer la relance 2","Attendre la réponse"),IF(K20="Relance 2 faite","Si rien sous 3 jours : Sans réponse",IF(K20="A répondu","Envoyer message 2 + vidéo workflow",IF(K20="Démo prévue","Préparer la démo avec ses produits",IF(K20="Démo faite","Envoyer l'offre et le prix",IF(K20="Client","Installer et demander un avis","Fini")))))))) -> Envoyer message 1 + vidéo présentation
... A30: 48 | B30: 2 | C30: A | D30: KYRA KINSHASA | E30: Kinshasa | F30: +243 815 953 082 | G30: Ouvrir WhatsApp | H30: Cosmetique | I30: Cosmétique et parfumerie | K30: À contacter | L30: =IF(J30="","",J30+3) | M30: =IF(J30="","",J30+7) | N30: =IF(K30="À contacter","Envoyer message 1 + vidéo présentation",IF(K30="Message envoyé",IF(J30="","Indiquer la date d'envoi",IF(TODAY()>=J30+3,"Envoyer la relance 1","Attendre la réponse")),IF(K30="Relance 1 faite",IF(TODAY()>=J30+7,"Envoyer la relance 2","Attendre la réponse"),IF(K30="Relance 2 faite","Si rien sous 3 jours : Sans réponse",IF(K30="A répondu","Envoyer message 2 + vidéo workflow",IF(K30="Démo prévue","Préparer la démo avec ses produits",IF(K30="Démo faite","Envoyer l'offre et le prix",IF(K30="Client","Installer et demander un avis","Fini")))))))) -> Envoyer message 1 + vidéo présentation
A31: 49 | B31: 2 | C31: A | D31: BRICOKIN | E31: Kinshasa | F31: +243 818 966 780 | G31: Ouvrir WhatsApp | H31: Cosmetique | I31: Cosmétique et parfumerie | K31: À contacter | L31: =IF(J31="","",J31+3) | M31: =IF(J31="","",J31+7) | N31: =IF(K31="À contacter","Envoyer message 1 + vidéo présentation",IF(K31="Message envoyé",IF(J31="","Indiquer la date d'envoi",IF(TODAY()>=J31+3,"Envoyer la relance 1","Attendre la réponse")),IF(K31="Relance 1 faite",IF(TODAY()>=J31+7,"Envoyer la relance 2","Attendre la réponse"),IF(K31="Relance 2 faite","Si rien sous 3 jours : Sans réponse",IF(K31="A répondu","Envoyer message 2 + vidéo workflow",IF(K31="Démo prévue","Préparer la démo avec ses produits",IF(K31="Démo faite","Envoyer l'offre et le prix",IF(K31="Client","Installer et demander un avis","Fini")))))))) -> Envoyer message 1 + vidéo présentation | P31: Le nom évoque le bricolage alors que le type est « cosmétique » : vérifier
A32: 16 | B32: 2 | C32: A | D32: BORA COSMETIQUE | E32: Lubumbashi | F32: +243 826 918 127 | G32: Ouvrir WhatsApp | H32: Cosmetique | I32: Cosmétique et parfumerie | K32: À contacter | L32: =IF(J32="","",J32+3) | M32: =IF(J32="","",J32+7) | N32: =IF(K32="À contacter","Envoyer message 1 + vidéo présentation",IF(K32="Message envoyé",IF(J32="","Indiquer la date d'envoi",IF(TODAY()>=J32+3,"Envoyer la relance 1","Attendre la réponse")),IF(K32="Relance 1 faite",IF(TODAY()>=J32+7,"Envoyer la relance 2","Attendre la réponse"),IF(K32="Relance 2 faite","Si rien sous 3 jours : Sans réponse",IF(K32="A répondu","Envoyer message 2 + vidéo workflow",IF(K32="Démo prévue","Préparer la démo avec ses produits",IF(K32="Démo faite","Envoyer l'offre et le prix",IF(K32="Client","Installer et demander un avis","Fini")))))))) -> Envoyer message 1 + vidéo présentation
A33: 17 | B33: 2 | C33: A | D33: KYRA LUBUMBASHI | E33: Lubumbashi | F33: +243 998 885 902 | G33: Ouvrir WhatsApp | H33: Parfumerie | I33: Cosmétique et parfumerie | K33: À contacter | L33: =IF(J33="","",J33+3) | M33: =IF(J33="","",J33+7) | N33: =IF(K33="À contacter","Envoyer message 1 + vidéo présentation",IF(K33="Message envoyé",IF(J33="","Indiquer la date d'envoi",IF(TODAY()>=J33+3,"Envoyer la relance 1","Attendre la réponse")),IF(K33="Relance 1 faite",IF(TODAY()>=J33+7,"Envoyer la relance 2","Attendre la réponse"),IF(K33="Relance 2 faite","Si rien sous 3 jours : Sans réponse",IF(K33="A répondu","Envoyer message 2 + vidéo workflow",IF(K33="Démo prévue","Préparer la démo avec ses produits",IF(K33="Démo faite","Envoyer l'offre et le prix",IF(K33="Client","Installer et demander un avis","Fini")))))))) -> Envoyer message 1 + vidéo présentation
A34: 19 | B34: 2 | C34: A | D34: SHEILA COSMETICS GOLF | E34: Lubumbashi | F34: +243 811 874 359 | G34: Ouvrir WhatsApp | H34: Cosmetique | I34: Cosmétique et parfumerie | K34: À contacter | L34: =IF(J34="","",J34+3) | M34: =IF(J34="","",J34+7) | N34: =IF(K34="À contacter","Envoyer message 1 + vidéo présentation",IF(K34="Message envoyé",IF(J34="","Indiquer la date d'envoi",IF(TODAY()>=J34+3,"Envoyer la relance 1","Attendre la réponse")),IF(K34="Relance 1 faite",IF(TODAY()>=J34+7,"Envoyer la relance 2","Attendre la réponse"),IF(K34="Relance 2 faite","Si rien sous 3 jours : Sans réponse",IF(K34="A répondu","Envoyer message 2 + vidéo workflow",IF(K34="Démo prévue","Préparer la démo avec ses produits",IF(K34="Démo faite","Envoyer l'offre et le prix",IF(K34="Client","Installer et demander un avis","Fini")))))))) -> Envoyer message 1 + vidéo présentation
A35: 25 | B35: 2 | C35: A | D35: PARFUMERIE ARCHE DE DIEU | E35: Lubumbashi | F35: +243 976 884 155 | G35: Ouvrir WhatsApp | H35: Cosmetique | I35: Cosmétique et parfumerie | K35: À contacter | L35: =IF(J35="","",J35+3) | M35: =IF(J35="","",J35+7) | N35: =IF(K35="À contacter","Envoyer message 1 + vidéo présentation",IF(K35="Message envoyé",IF(J35="","Indiquer la date d'envoi",IF(TODAY()>=J35+3,"Envoyer la relance 1","Attendre la réponse")),IF(K35="Relance 1 faite",IF(TODAY()>=J35+7,"Envoyer la relance 2","Attendre la réponse"),IF(K35="Relance 2 faite","Si rien sous 3 jours : Sans réponse",IF(K35="A répondu","Envoyer message 2 + vidéo workflow",IF(K35="Démo prévue","Préparer la démo avec ses produits",IF(K35="Démo faite","Envoyer l'offre et le prix",IF(K35="Client","Installer et demander un avis","Fini")))))))) -> Envoyer message 1 + vidéo présentation
A36: 2 | B36: 2 | C36: A | D36: ENTREPRISE CPC | E36: Kinshasa | F36: +243 998 357 214 | G36: Ouvrir WhatsApp | H36: Peinture batiment | I36: Quincaillerie et peinture | K36: À contacter | L36: =IF(J36="","",J36+3) | M36: =IF(J36="","",J36+7) | N36: =IF(K36="À contacter","Envoyer message 1 + vidéo présentation",IF(K36="Message envoyé",IF(J36="","Indiquer la date d'envoi",IF(TODAY()>=J36+3,"Envoyer la relance 1","Attendre la réponse")),IF(K36="Relance 1 faite",IF(TODAY()>=J36+7,"Envoyer la relance 2","Attendre la réponse"),IF(K36="Relance 2 faite","Si rien sous 3 jours : Sans réponse",IF(K36="A répondu","Envoyer message 2 + vidéo workflow",IF(K36="Démo prévue","Préparer la démo avec ses produits",IF(K36="Démo faite","Envoyer l'offre et le prix",IF(K36="Client","Installer et demander un avis","Fini")))))))) -> Envoyer message 1 + vidéo présentation
A37: 6 | B37: 2 | C37: A | D37: QUIN LEY SARLU | E37: Lubumbashi | F37: +243 843 006 054 | G37: Ouvrir WhatsApp | H37: Quincailleries | I37: Quincaillerie et peinture | K37: À contacter | L37: =IF(J37="","",J37+3) | M37: =IF(J37="","",J37+7) | N37: =IF(K37="À contacter","Envoyer message 1 + vidéo présentation",IF(K37="Message envoyé",IF(J37="","Indiquer la date d'envoi",IF(TODAY()>=J37+3,"Envoyer la relance 1","Attendre la réponse")),IF(K37="Relance 1 faite",IF(TODAY()>=J37+7,"Envoyer la relance 2","Attendre la réponse"),IF(K37="Relance 2 faite","Si rien sous 3 jours : Sans réponse",IF(K37="A répondu","Envoyer message 2 + vidéo workflow",IF(K37="Démo prévue","Préparer la démo avec ses produits",IF(K37="Démo faite","Envoyer l'offre et le prix",IF(K37="Client","Installer et demander un avis","Fini")))))))) -> Envoyer message 1 + vidéo présentation
A38: 7 | B38: 2 | C38: A | D38: KYUMACO | E38: Lubumbashi | F38: +243 907 784 433 | G38: Ouvrir WhatsApp | H38: Quincailleries | I38: Quincaillerie et peinture | K38: À contacter | L38: =IF(J38="","",J38+3) | M38: =IF(J38="","",J38+7) | N38: =IF(K38="À contacter","Envoyer message 1 + vidéo présentation",IF(K38="Message envoyé",IF(J38="","Indiquer la date d'envoi",IF(TODAY()>=J38+3,"Envoyer la relance 1","Attendre la réponse")),IF(K38="Relance 1 faite",IF(TODAY()>=J38+7,"Envoyer la relance 2","Attendre la réponse"),IF(K38="Relance 2 faite","Si rien sous 3 jours : Sans réponse",IF(K38="A répondu","Envoyer message 2 + vidéo workflow",IF(K38="Démo prévue","Préparer la démo avec ses produits",IF(K38="Démo faite","Envoyer l'offre et le prix",IF(K38="Client","Installer et demander un avis","Fini")))))))) -> Envoyer message 1 + vidéo présentation
A39: 14 | B39: 2 | C39: A | D39: QUINMAT | E39: Lubumbashi | F39: +243 824 130 000 | G39: Ouvrir WhatsApp | H39: Quincailleries | I39: Quincaillerie et peinture | K39: À contacter | L39: =IF(J39="","",J39+3) | M39: =IF(J39="","",J39+7) | N39: =IF(K39="À contacter","Envoyer message 1 + vidéo présentation",IF(K39="Message envoyé",IF(J39="","Indiquer la date d'envoi",IF(TODAY()>=J39+3,"Envoyer la relance 1","Attendre la réponse")),IF(K39="Relance 1 faite",IF(TODAY()>=J39+7,"Envoyer la relance 2","Attendre la réponse"),IF(K39="Relance 2 faite","Si rien sous 3 jours : Sans réponse",IF(K39="A répondu","Envoyer message 2 + vidéo workflow",IF(K39="Démo prévue","Préparer la démo avec ses produits",IF(K39="Démo faite","Envoyer l'offre et le prix",IF(K39="Client","Installer et demander un avis","Fini")))))))) -> Envoyer message 1 + vidéo présentation
A40: 15 | B40: 2 | C40: A | D40: M'SIRI QUINCAILLERIE & DIVERS | E40: Lubumbashi | F40: +243 816 785 109 | G40: Ouvrir WhatsApp | H40: Quincailleries | I40: Quincaillerie et peinture | K40: À contacter | L40: =IF(J40="","",J40+3) | M40: =IF(J40="","",J40+7) | N40: =IF(K40="À contacter","Envoyer message 1 + vidéo présentation",IF(K40="Message envoyé",IF(J40="","Indiquer la date d'envoi",IF(TODAY()>=J40+3,"Envoyer la relance 1","Attendre la réponse")),IF(K40="Relance 1 faite",IF(TODAY()>=J40+7,"Envoyer la relance 2","Attendre la réponse"),IF(K40="Relance 2 faite","Si rien sous 3 jours : Sans réponse",IF(K40="A répondu","Envoyer message 2 + vidéo workflow",IF(K40="Démo prévue","Préparer la démo avec ses produits",IF(K40="Démo faite","Envoyer l'offre et le prix",IF(K40="Client","Installer et demander un avis","Fini")))))))) -> Envoyer message 1 + vidéo présentation
A41: 1 | B41: 3 | C41: C | D41: PREDI B | E41: ? | F41: +90 533 835 38 57 | G41: Ouvrir WhatsApp | H41: Cosmetique | I41: Cosmétique et parfumerie | K41: À contacter | L41: =IF(J41="","",J41+3) | M41: =IF(J41="","",J41+7) | N41: =IF(K41="À contacter","Envoyer message 1 + vidéo présentation",IF(K41="Message envoyé",IF(J41="","Indiquer la date d'envoi",IF(TODAY()>=J41+3,"Envoyer la relance 1","Attendre la réponse")),IF(K41="Relance 1 faite",IF(TODAY()>=J41+7,"Envoyer la relance 2","Attendre la réponse"),IF(K41="Relance 2 faite","Si rien sous 3 jours : Sans réponse",IF(K41="A répondu","Envoyer message 2 + vidéo workflow",IF(K41="Démo prévue","Préparer la démo avec ses produits",IF(K41="Démo faite","Envoyer l'offre et le prix",IF(K41="Client","Installer et demander un avis","Fini")))))))) -> Envoyer message 1 + vidéo présentation | P41: Ville manquante. Numéro hors RDC (+90 = Turquie) : vérifier avant d'écrire
A42: 3 | B42: 3 | C42: B | D42: YAF YAF | E42: Kinshasa | F42: +243 903 045 773 | G42: Ouvrir WhatsApp | H42: Boutique d'habillement | I42: Habillement | K42: À contacter | L42: =IF(J42="","",J42+3) | M42: =IF(J42="","",J42+7) | N42: =IF(K42="À contacter","Envoyer message 1 + vidéo présentation",IF(K42="Message envoyé",IF(J42="","Indiquer la date d'envoi",IF(TODAY()>=J42+3,"Envoyer la relance 1","Attendre la réponse")),IF(K42="Relance 1 faite",IF(TODAY()>=J42+7,"Envoyer la relance 2","Attendre la réponse"),IF(K42="Relance 2 faite","Si rien sous 3 jours : Sans réponse",IF(K42="A répondu","Envoyer message 2 + vidéo workflow",IF(K42="Démo prévue","Préparer la démo avec ses produits",IF(K42="Démo faite","Envoyer l'offre et le prix",IF(K42="Client","Installer et demander un avis","Fini")))))))) -> Envoyer message 1 + vidéo présentation
A43: 43 | B43: 3 | C43: B | D43: PERLUNA STORE | E43: Kinshasa | F43: +243 848 405 000 | G43: Ouvrir WhatsApp | H43: Habillement | I43: Habillement | K43: À contacter | L43: =IF(J43="","",J43+3) | M43: =IF(J43="","",J43+7) | N43: =IF(K43="À contacter","Envoyer message 1 + vidéo présentation",IF(K43="Message envoyé",IF(J43="","Indiquer la date d'envoi",IF(TODAY()>=J43+3,"Envoyer la relance 1","Attendre la réponse")),IF(K43="Relance 1 faite",IF(TODAY()>=J43+7,"Envoyer la relance 2","Attendre la réponse"),IF(K43="Relance 2 faite","Si rien sous 3 jours : Sans réponse",IF(K43="A répondu","Envoyer message 2 + vidéo workflow",IF(K43="Démo prévue","Préparer la démo avec ses produits",IF(K43="Démo faite","Envoyer l'offre et le prix",IF(K43="Client","Installer et demander un avis","Fini")))))))) -> Envoyer message 1 + vidéo présentation
A44: 50 | B44: 3 | C44: B | D44: EGRA BOUTIQUE | E44: Kinshasa | F44: +243 856 316 267 | G44: Ouvrir WhatsApp | H44: Habillement femme | I44: Habillement | K44: À contacter | L44: =IF(J44="","",J44+3) | M44: =IF(J44="","",J44+7) | N44: =IF(K44="À contacter","Envoyer message 1 + vidéo présentation",IF(K44="Message envoyé",IF(J44="","Indiquer la date d'envoi",IF(TODAY()>=J44+3,"Envoyer la relance 1","Attendre la réponse")),IF(K44="Relance 1 faite",IF(TODAY()>=J44+7,"Envoyer la relance 2","Attendre la réponse"),IF(K44="Relance 2 faite","Si rien sous 3 jours : Sans réponse",IF(K44="A répondu","Envoyer message 2 + vidéo workflow",IF(K44="Démo prévue","Préparer la démo avec ses produits",IF(K44="Démo faite","Envoyer l'offre et le prix",IF(K44="Client","Installer et demander un avis","Fini")))))))) -> Envoyer message 1 + vidéo présentation
A45: 23 | B45: 3 | C45: B | D45: SCHOLA BEAUTY AND SERVICE | E45: Lubumbashi | F45: +243 827 812 704 | G45: Ouvrir WhatsApp | H45: Habillement et divers femme | I45: Habillement | K45: À contacter | L45: =IF(J45="","",J45+3) | M45: =IF(J45="","",J45+7) | N45: =IF(K45="À contacter","Envoyer message 1 + vidéo présentation",IF(K45="Message envoyé",IF(J45="","Indiquer la date d'envoi",IF(TODAY()>=J45+3,"Envoyer la relance 1","Attendre la réponse")),IF(K45="Relance 1 faite",IF(TODAY()>=J45+7,"Envoyer la relance 2","Attendre la réponse"),IF(K45="Relance 2 faite","Si rien sous 3 jours : Sans réponse",IF(K45="A répondu","Envoyer message 2 + vidéo workflow",IF(K45="Démo prévue","Préparer la démo avec ses produits",IF(K45="Démo faite","Envoyer l'offre et le prix",IF(K45="Client","Installer et demander un avis","Fini")))))))) -> Envoyer message 1 + vidéo présentation
A46: 9 | B46: 3 | C46: B | D46: AMICONGO LUBUMBASHI | E46: Lubumbashi | F46: +243 997 408 340 | G46: Ouvrir WhatsApp | H46: Entrepot | I46: Entrepôt et distribution | K46: À contacter | L46: =IF(J46="","",J46+3) | M46: =IF(J46="","",J46+7) | N46: =IF(K46="À contacter","Envoyer message 1 + vidéo présentation",IF(K46="Message envoyé",IF(J46="","Indiquer la date d'envoi",IF(TODAY()>=J46+3,"Envoyer la relance 1","Attendre la réponse")),IF(K46="Relance 1 faite",IF(TODAY()>=J46+7,"Envoyer la relance 2","Attendre la réponse"),IF(K46="Relance 2 faite","Si rien sous 3 jours : Sans réponse",IF(K46="A répondu","Envoyer message 2 + vidéo workflow",IF(K46="Démo prévue","Préparer la démo avec ses produits",IF(K46="Démo faite","Envoyer l'offre et le prix",IF(K46="Client","Installer et demander un avis","Fini")))))))) -> Envoyer message 1 + vidéo présentation
A47: 13 | B47: 3 | C47: B | D47: ETS TROPICAL PRODUCTS | E47: Lubumbashi | F47: +243 997 024 727 | G47: Ouvrir WhatsApp | H47: Production et distribution d'eau | I47: Entrepôt et distribution | K47: À contacter | L47: =IF(J47="","",J47+3) | M47: =IF(J47="","",J47+7) | N47: =IF(K47="À contacter","Envoyer message 1 + vidéo présentation",IF(K47="Message envoyé",IF(J47="","Indiquer la date d'envoi",IF(TODAY()>=J47+3,"Envoyer la relance 1","Attendre la réponse")),IF(K47="Relance 1 faite",IF(TODAY()>=J47+7,"Envoyer la relance 2","Attendre la réponse"),IF(K47="Relance 2 faite","Si rien sous 3 jours : Sans réponse",IF(K47="A répondu","Envoyer message 2 + vidéo workflow",IF(K47="Démo prévue","Préparer la démo avec ses produits",IF(K47="Démo faite","Envoyer l'offre et le prix",IF(K47="Client","Installer et demander un avis","Fini")))))))) -> Envoyer message 1 + vidéo présentation
A48: 24 | B48: 3 | C48: C | D48: KEMBEZI PHARMA CARE | E48: Lubumbashi | F48: +243 856 152 457 | G48: Ouvrir WhatsApp | H48: Pharmaceutique | I48: Pharmacie | K48: À contacter | L48: =IF(J48="","",J48+3) | M48: =IF(J48="","",J48+7) | N48: =IF(K48="À contacter","Envoyer message 1 + vidéo présentation",IF(K48="Message envoyé",IF(J48="","Indiquer la date d'envoi",IF(TODAY()>=J48+3,"Envoyer la relance 1","Attendre la réponse")),IF(K48="Relance 1 faite",IF(TODAY()>=J48+7,"Envoyer la relance 2","Attendre la réponse"),IF(K48="Relance 2 faite","Si rien sous 3 jours : Sans réponse",IF(K48="A répondu","Envoyer message 2 + vidéo workflow",IF(K48="Démo prévue","Préparer la démo avec ses produits",IF(K48="Démo faite","Envoyer l'offre et le prix",IF(K48="Client","Installer et demander un avis","Fini")))))))) -> Envoyer message 1 + vidéo présentation | P48: Attendre la colonne « date de péremption » dans le template
A49: 31 | B49: 3 | C49: C | D49: ZOTTOSPHARMA | E49: Lubumbashi | F49: +243 818 151 111 | G49: Ouvrir WhatsApp | H49: Pharmacie | I49: Pharmacie | K49: À contacter | L49: =IF(J49="","",J49+3) | M49: =IF(J49="","",J49+7) | N49: =IF(K49="À contacter","Envoyer message 1 + vidéo présentation",IF(K49="Message envoyé",IF(J49="","Indiquer la date d'envoi",IF(TODAY()>=J49+3,"Envoyer la relance 1","Attendre la réponse")),IF(K49="Relance 1 faite",IF(TODAY()>=J49+7,"Envoyer la relance 2","Attendre la réponse"),IF(K49="Relance 2 faite","Si rien sous 3 jours : Sans réponse",IF(K49="A répondu","Envoyer message 2 + vidéo workflow",IF(K49="Démo prévue","Préparer la démo avec ses produits",IF(K49="Démo faite","Envoyer l'offre et le prix",IF(K49="Client","Installer et demander un avis","Fini")))))))) -> Envoyer message 1 + vidéo présentation | P49: Attendre la colonne « date de péremption » dans le template
A50: 8 | B50: 3 | C50: C | D50: BETA CONSTRUCTION | E50: Lubumbashi | F50: +243 999 273 585 | G50: Ouvrir WhatsApp | H50: Construction | I50: À vérifier | K50: À contacter | L50: =IF(J50="","",J50+3) | M50: =IF(J50="","",J50+7) | N50: =IF(K50="À contacter","Envoyer message 1 + vidéo présentation",IF(K50="Message envoyé",IF(J50="","Indiquer la date d'envoi",IF(TODAY()>=J50+3,"Envoyer la relance 1","Attendre la réponse")),IF(K50="Relance 1 faite",IF(TODAY()>=J50+7,"Envoyer la relance 2","Attendre la réponse"),IF(K50="Relance 2 faite","Si rien sous 3 jours : Sans réponse",IF(K50="A répondu","Envoyer message 2 + vidéo workflow",IF(K50="Démo prévue","Préparer la démo avec ses produits",IF(K50="Démo faite","Envoyer l'offre et le prix",IF(K50="Client","Installer et demander un avis","Fini")))))))) -> Envoyer message 1 + vidéo présentation | P50: Besoin de stock à confirmer (service ou chantier, pas une boutique)
...

Sheet Messages
A1: Les messages (vous)
A3: Message 1 (jour 0) + vidéo de présentation | B3: Bonjour [Nom] 👋 Je suis Mike, d'Allegra Digital Ground. Avec tous vos modèles, accessoires et pièces, savoir exactement ce qu'il reste en stock prend vite du temps. On a créé un système simple : vous notez vos ventes et vos arrivages depuis votre téléphone, le stock se calcule tout seul, et vous recevez sur WhatsApp les alertes de stock bas et le bilan du soir. Je vous envoie une vidéo de 37 secondes qui montre comment ça marche 👇 Petite question : aujourd'hui, comment suivez-vous votre stock ? Cahier, Excel, ou de tête ?
A4: Phrase d'accroche selon le segment | B4: • Téléphones, électronique, informatique : Avec tous vos modèles, accessoires et pièces, savoir exactement ce qu'il reste en stock prend vite du temps. • Cosmétique et parfumerie : Avec autant de références, il arrive qu'un produit manque sans qu'on l'ait vu venir, ou qu'on dise « c'est fini » alors qu'il en restait. • Quincaillerie et peinture : Dans une quincaillerie, le stock coûte cher. Savoir ce qu'il reste et ce qu'il vaut, sans tout recompter, change beaucoup de choses. • Habillement : Entre les modèles, les tailles et les couleurs, savoir tout de suite si un article est encore disponible n'est pas toujours simple. • Entrepôt et distribution : Quand la marchandise entre et sort tous les jours, garder un stock juste et savoir quoi recommander devient vite un travail à plein temps. • Pharmacie : Avec autant de références, une rupture passe vite inaperçue, et un client qui ne trouve pas son produit va ailleurs. • À vérifier : Quand la marchandise entre et sort tous les jours, garder un stock juste prend vite du temps.
A5: Message 2 (s'il répond) + vidéo du workflow | B5: Merci pour votre réponse 🙏 Voici ce qui se passe à l'intérieur du système, étape par étape (35 secondes) 👇 Je vous propose de vous le montrer avec vos propres produits, en appel vidéo WhatsApp de 15 minutes. Quel jour vous arrange cette semaine ?
A6: Relance 1 (jour 3) | B6: Bonjour [Nom], je reviens vers vous pour la petite vidéo envoyée il y a quelques jours. Le suivi du stock, c'est un sujet chez vous en ce moment ? Un simple oui ou non m'aide déjà 🙏
A7: Relance 2 (jour 7, la dernière) | B7: Bonjour [Nom], dernier message de ma part sur ce sujet. Si un jour vous voulez voir le système avec vos produits, répondez simplement « STOCK » et je vous le montre en 15 minutes. Bonne journée !
